Workbook

Sheet Title Page
B2: This spreadsheet supports STUDENT analysis of the case “Outsourcing, Near-sourcing, and Supply Chain Flexibility in the Apparel Industry (A)” (UVA-QA-0854).
A4: This spreadsheet was prepared by Anton Ovchinnikov, Distinguished Faculty Professor of Management Science and Operations Management and Scotiabank Scholar of Customer Analytics at the Smith School of Business, Queen’s University, Canada. Copyright © 2016 by the University of Virginia Darden School Foundation, Charlottesville, VA. All rights reserved. For customer service inquiries, send an email tosales@dardenbusinesspublishing.com. No part of this publication may be reproduced, stored in a retrieval system, posted to the Internet, or transmitted in any form or by any means—electronic, mechanical, photocopying, recording, or otherwise—without the permission of the Darden School Foundation. Our goal is to publish materials of the highest quality, so please submit any errata to editorial@dardenbusinesspublishing.com.
A5: Oct. 14, 2016

Sheet Sales Data
C2: Exhibit 1
A3: Outsourcing, Near-sourcing, and Supply Chain Flexibility in the Apparel Industry (A)
A4: Daily Sales
C7: Date | D7: LEC ID | E7: Units Sold
C8: 41282 | D8: 1 | E8: 40
C9: 41283 | D9: 1 | E9: 5
C10: 41284 | D10: 1 | E10: 14
C11: 41285 | D11: 1 | E11: 8
C12: 41286 | D12: 1 | E12: 4
C13: 41287 | D13: 1 | E13: 13
C14: 41288 | D14: 1 | E14: 9
C15: 41289 | D15: 1 | E15: 8
C16: 41290 | D16: 1 | E16: 5
C17: 41291 | D17: 1 | E17: 5
C18: 41292 | D18: 1 | E18: 3
C19: 41293 | D19: 1 | E19: 1
... C425: 41700 | D425: 23 | E425: 49
C427: Source: Created by author.

Sheet Data Viz
A3: Sum of Units Sold | B3: Column Labels
A4: Row Labels | B4: 1 | C4: 2 | D4: 3 | E4: 4 | F4: 5 | G4: 6 | H4: 7 | I4: 8 | J4: 9 | K4: 10 | L4: 11 | M4: 12 | N4: 13 | O4: 14 | P4: 15 | Q4: 16 | R4: 17 | S4: 18 | T4: 19 | U4: 20 | V4: 21 | W4: 22 | X4: 23 | Y4: Grand Total
A5: 41282 | B5: 40 | Y5: 40
A6: 41283 | B6: 5 | Y6: 5
A7: 41284 | B7: 14 | Y7: 14
A8: 41285 | B8: 8 | Y8: 8
A9: 41286 | B9: 4 | Y9: 4
A10: 41287 | B10: 13 | Y10: 13
A11: 41288 | B11: 9 | Y11: 9
A12: 41289 | B12: 8 | Y12: 8
A13: 41290 | B13: 5 | Y13: 5
A14: 41291 | B14: 5 | Y14: 5
A15: 41292 | B15: 3 | Y15: 3
A16: 41293 | B16: 1 | Y16: 1
... A25: 41302 | B25: 4 | Y25: 4
A26: 41303 | C26: 32 | Y26: 32
A27: 41304 | C27: 11 | Y27: 11
A28: 41305 | C28: 3 | Y28: 3
A29: 41306 | C29: 15 | Y29: 15
A30: 41307 | C30: 14 | Y30: 14
A31: 41308 | C31: 17 | Y31: 17
A32: 41309 | C32: 16 | Y32: 16
A33: 41310 | C33: 8 | Y33: 8
A34: 41311 | C34: 9 | Y34: 9
A35: 41312 | C35: 10 | Y35: 10
A36: 41313 | C36: 8 | Y36: 8
A37: 41314 | C37: 3 | Y37: 3
... A45: 41323 | C45: 9 | Y45: 9
A46: 41324 | D46: 42 | Y46: 42
A47: 41325 | D47: 20 | Y47: 20
A48: 41326 | D48: 25 | Y48: 25
A49: 41327 | D49: 23 | Y49: 23
A50: 41328 | D50: 22 | Y50: 22
A51: 41329 | D51: 18 | Y51: 18
A52: 41330 | D52: 5 | Y52: 5
A53: 41331 | D53: 9 | Y53: 9
A54: 41332 | D54: 3 | Y54: 3
A55: 41333 | D55: 15 | Y55: 15
A56: 41334 | D56: 6 | Y56: 6
A57: 41335 | D57: 3 | Y57: 3
...

Sheet Regression
A1: LEC ID | B1: Length | C1: Ln(Length) | D1: Normalized Ln(Len) | E1: Contains Holiday | F1: Total Sold
A2: 1 | B2: 21 | C2: =LN(B2) -> 3.0445224 | D2: =(C2-$B$26)/$B$27 -> 0.61827231 | E2: 0 | F2: 173
A3: 2 | B3: 20 | C3: =LN(B3) -> 2.9957323 | D3: =(C3-$B$26)/$B$27 -> 0.46738262 | E3: 0 | F3: 196
A4: 3 | B4: 13 | C4: =LN(B4) -> 2.5649494 | D4: =(C4-$B$26)/$B$27 -> -0.86486743 | E4: 0 | F4: 195 | H4: Regression Ln(Len)
A5: 4 | B5: 15 | C5: =LN(B5) -> 2.7080502 | D5: =(C5-$B$26)/$B$27 -> -0.42231017 | E5: 0 | F5: 210
A6: 5 | B6: 13 | C6: =LN(B6) -> 2.5649494 | D6: =(C6-$B$26)/$B$27 -> -0.86486743 | E6: 0 | F6: 291 | H6: Regression Statistics
A7: 6 | B7: 14 | C7: =LN(B7) -> 2.6390573 | D7: =(C7-$B$26)/$B$27 -> -0.63567925 | E7: 0 | F7: 170 | H7: Multiple R | I7: 0.93935473
A8: 7 | B8: 15 | C8: =LN(B8) -> 2.7080502 | D8: =(C8-$B$26)/$B$27 -> -0.42231017 | E8: 0 | F8: 252 | H8: R Square | I8: 0.88238731
A9: 8 | B9: 21 | C9: =LN(B9) -> 3.0445224 | D9: =(C9-$B$26)/$B$27 -> 0.61827231 | E9: 0 | F9: 520 | H9: Adjusted R Square | I9: 0.87062604
A10: 9 | B10: 14 | C10: =LN(B10) -> 2.6390573 | D10: =(C10-$B$26)/$B$27 -> -0.63567925 | E10: 0 | F10: 164 | H10: Standard Error | I10: 105.97785
A11: 10 | B11: 14 | C11: =LN(B11) -> 2.6390573 | D11: =(C11-$B$26)/$B$27 -> -0.63567925 | E11: 0 | F11: 135 | H11: Observations | I11: 23
A12: 11 | B12: 14 | C12: =LN(B12) -> 2.6390573 | D12: =(C12-$B$26)/$B$27 -> -0.63567925 | E12: 0 | F12: 153
A13: 12 | B13: 16 | C13: =LN(B13) -> 2.7725887 | D13: =(C13-$B$26)/$B$27 -> -0.22271672 | E13: 0 | F13: 322 | H13: ANOVA
A14: 13 | B14: 26 | C14: =LN(B14) -> 3.2580965 | D14: =(C14-$B$26)/$B$27 -> 1.2787769 | E14: 0 | F14: 298 | I14: df | J14: SS | K14: MS | L14: F | M14: Significance F
A15: 14 | B15: 16 | C15: =LN(B15) -> 2.7725887 | D15: =(C15-$B$26)/$B$27 -> -0.22271672 | E15: 0 | F15: 133 | H15: Regression | I15: 2 | J15: 1685253.6 | K15: 842626.78 | L15: 75.024837 | M15: 5.0645624e-10
A16: 15 | B16: 18 | C16: =LN(B16) -> 2.8903718 | D16: =(C16-$B$26)/$B$27 -> 0.14154205 | E16: 0 | F16: 192 | H16: Residual | I16: 20 | J16: 224626.09 | K16: 11231.304
A17: 16 | B17: 14 | C17: =LN(B17) -> 2.6390573 | D17: =(C17-$B$26)/$B$27 -> -0.63567925 | E17: 0 | F17: 198 | H17: Total | I17: 22 | J17: 1909879.7
A18: 17 | B18: 36 | C18: =LN(B18) -> 3.5835189 | D18: =(C18-$B$26)/$B$27 -> 2.2851864 | E18: 1 | F18: 991
A19: 18 | B19: 35 | C19: =LN(B19) -> 3.5553481 | D19: =(C19-$B$26)/$B$27 -> 2.1980644 | E19: 1 | F19: 1244 | I19: Coefficients | J19: Standard Error | K19: t Stat | L19: P-value | M19: Lower 95% | N19: Upper 95% | O19: Lower 95,0% | P19: Upper 95,0%
A20: 19 | B20: 28 | C20: =LN(B20) -> 3.3322045 | D20: =(C20-$B$26)/$B$27 -> 1.5079651 | E20: 1 | F20: 855 | H20: Intercept | I20: 252.10198 | J20: 26.15096 | K20: 9.640257 | L20: 5.8370928e-09 | M20: 197.55203 | N20: 306.65192 | O20: 197.55203 | P20: 306.65192
A21: 20 | B21: 17 | C21: =LN(B21) -> 2.8332133 | D21: =(C21-$B$26)/$B$27 -> -0.035227495 | E21: 0 | F21: 291 | H21: X Variable 1 | I21: 61.429857 | J21: 36.918288 | K21: 1.6639411 | L21: 0.11171494 | M21: -15.580343 | N21: 138.44006 | O21: -15.580343 | P21: 138.44006
A22: 21 | B22: 11 | C22: =LN(B22) -> 2.3978953 | D22: =(C22-$B$26)/$B$27 -> -1.3815031 | E22: 0 | F22: 143 | H22: X Variable 2 | I22: 655.21818 | J22: 107.21146 | K22: 6.1114568 | L22: 5.6761052e-06 | M22: 431.579 | N22: 878.85735 | O22: 431.579 | P22: 878.85735
A23: 22 | B23: 14 | C23: =LN(B23) -> 2.6390573 | D23: =(C23-$B$26)/$B$27 -> -0.63567925 | E23: 0 | F23: 253
A24: 23 | B24: 13 | C24: =LN(B24) -> 2.5649494 | D24: =(C24-$B$26)/$B$27 -> -0.86486743 | E24: 0 | F24: 385
A26: Mean Ln(Len) | B26: =AVERAGE(C2:C24) -> 2.8446042
A27: Std.Dev. Ln(Len) | B27: =_xlfn.STDEV.S(C2:C24) -> 0.3233499

Sheet Task 3
A1: LEC ID | B1: Length | C1: Normalized Ln(Length) | D1: Contains Holiday | E1: Prediction | F1: Interpretation: Cost of overordering ($65) Is slightly more than underordering ($70), so we can be slightly aggressive and order more than expected
A2: 24 | B2: 21 | C2: =(LN(B2)-Regression!B26)/Regression!B27 -> 0.61827231 | D2: 0 | E2: =Regression!I20+'Task 3'!C2*Regression!I21+'Task 3'!D2*Regression!I22 -> 290.08236
A4: Cost/Item | B4: 65
A5: Revenue/item | B5: 135
A6: Expected | B6: =E2 -> 290.08236
A7: Std. Error | B7: =Regression!I10 -> 105.97785
A9: Order Size | B9: =_xlfn.FLOOR.MATH(E2) -> 290
A10: Avg Profit | B10: =AVERAGE(H16:H1000) -> 14336.426
A12: Best Profit | B12: =MAX(K15:K415) -> 15013.178
A13: Best Order Size | B13: =_xlfn.XLOOKUP(B12,K15:K415,J15:J415,0,0,1) -> 287 | J13: Order Size | K13: Avg. Profit
K14: =B10 -> 14336.426
B15: Rand | C15: Demand | D15: Order | E15: Sold | F15: Cost | G15: Price | H15: Profit | J15: 100 | K15: 6821.0051
B16: =RAND() -> 0.29581742 | C16: =_xlfn.FLOOR.MATH(_xlfn.NORM.INV(B16,$B$6,$B$7)) -> 233 | D16: =$B$9 -> 290 | E16: =_xlfn.FLOOR.MATH(MIN(C16,D16)) -> 233 | F16: 65 | G16: 135 | H16: =E16*G16-D16*F16 -> 12605 | J16: 101 | K16: 6752.8528
B17: =RAND() -> 0.10797112 | C17: =_xlfn.FLOOR.MATH(_xlfn.NORM.INV(B17,$B$6,$B$7)) -> 158 | D17: =$B$9 -> 290 | E17: =_xlfn.FLOOR.MATH(MIN(C17,D17)) -> 158 | F17: 65 | G17: 135 | H17: =E17*G17-D17*F17 -> 2480 | J17: 102 | K17: 6928.6599
B18: =RAND() -> 0.94984566 | C18: =_xlfn.FLOOR.MATH(_xlfn.NORM.INV(B18,$B$6,$B$7)) -> 464 | D18: =$B$9 -> 290 | E18: =_xlfn.FLOOR.MATH(MIN(C18,D18)) -> 290 | F18: 65 | G18: 135 | H18: =E18*G18-D18*F18 -> 20300 | J18: 103 | K18: 7024.7005
B19: =RAND() -> 0.4377353 | C19: =_xlfn.FLOOR.MATH(_xlfn.NORM.INV(B19,$B$6,$B$7)) -> 273 | D19: =$B$9 -> 290 | E19: =_xlfn.FLOOR.MATH(MIN(C19,D19)) -> 273 | F19: 65 | G19: 135 | H19: =E19*G19-D19*F19 -> 18005 | J19: 104 | K19: 7093.0558
B20: =RAND() -> 0.33999597 | C20: =_xlfn.FLOOR.MATH(_xlfn.NORM.INV(B20,$B$6,$B$7)) -> 246 | D20: =$B$9 -> 290 | E20: =_xlfn.FLOOR.MATH(MIN(C20,D20)) -> 246 | F20: 65 | G20: 135 | H20: =E20*G20-D20*F20 -> 14360 | J20: 105 | K20: 7173.8832
B21: =RAND() -> 0.077042824 | C21: =_xlfn.FLOOR.MATH(_xlfn.NORM.INV(B21,$B$6,$B$7)) -> 139 | D21: =$B$9 -> 290 | E21: =_xlfn.FLOOR.MATH(MIN(C21,D21)) -> 139 | F21: 65 | G21: 135 | H21: =E21*G21-D21*F21 -> -85 | J21: 106 | K21: 7106.9645
B22: =RAND() -> 0.54508749 | C22: =_xlfn.FLOOR.MATH(_xlfn.NORM.INV(B22,$B$6,$B$7)) -> 302 | D22: =$B$9 -> 290 | E22: =_xlfn.FLOOR.MATH(MIN(C22,D22)) -> 290 | F22: 65 | G22: 135 | H22: =E22*G22-D22*F22 -> 20300 | J22: 107 | K22: 7209.7208
B23: =RAND() -> 0.93735624 | C23: =_xlfn.FLOOR.MATH(_xlfn.NORM.INV(B23,$B$6,$B$7)) -> 452 | D23: =$B$9 -> 290 | E23: =_xlfn.FLOOR.MATH(MIN(C23,D23)) -> 290 | F23: 65 | G23: 135 | H23: =E23*G23-D23*F23 -> 20300 | J23: 108 | K23: 7236
B24: =RAND() -> 0.53101049 | C24: =_xlfn.FLOOR.MATH(_xlfn.NORM.INV(B24,$B$6,$B$7)) -> 298 | D24: =$B$9 -> 290 | E24: =_xlfn.FLOOR.MATH(MIN(C24,D24)) -> 290 | F24: 65 | G24: 135 | H24: =E24*G24-D24*F24 -> 20300 | J24: 109 | K24: 7396.0457
B25: =RAND() -> 0.81240276 | C25: =_xlfn.FLOOR.MATH(_xlfn.NORM.INV(B25,$B$6,$B$7)) -> 384 | D25: =$B$9 -> 290 | E25: =_xlfn.FLOOR.MATH(MIN(C25,D25)) -> 290 | F25: 65 | G25: 135 | H25: =E25*G25-D25*F25 -> 20300 | J25: 110 | K25: 7439.0457
B26: =RAND() -> 0.051240126 | C26: =_xlfn.FLOOR.MATH(_xlfn.NORM.INV(B26,$B$6,$B$7)) -> 117 | D26: =$B$9 -> 290 | E26: =_xlfn.FLOOR.MATH(MIN(C26,D26)) -> 117 | F26: 65 | G26: 135 | H26: =E26*G26-D26*F26 -> -3055 | J26: 111 | K26: 7645.1421
B27: =RAND() -> 0.35639854 | C27: =_xlfn.FLOOR.MATH(_xlfn.NORM.INV(B27,$B$6,$B$7)) -> 251 | D27: =$B$9 -> 290 | E27: =_xlfn.FLOOR.MATH(MIN(C27,D27)) -> 251 | F27: 65 | G27: 135 | H27: =E27*G27-D27*F27 -> 15035 | J27: 112 | K27: 7618.3807
... B415: =RAND() -> 0.13645819 | C415: =_xlfn.FLOOR.MATH(_xlfn.NORM.INV(B415,$B$6,$B$7)) -> 173 | D415: =$B$9 -> 290 | E415: =_xlfn.FLOOR.MATH(MIN(C415,D415)) -> 173 | F415: 65 | G415: 135 | H415: =E415*G415-D415*F415 -> 4505 | J415: 500 | K415: 6449.2132
B416: =RAND() -> 0.86581838 | C416: =_xlfn.FLOOR.MATH(_xlfn.NORM.INV(B416,$B$6,$B$7)) -> 407 | D416: =$B$9 -> 290 | E416: =_xlfn.FLOOR.MATH(MIN(C416,D416)) -> 290 | F416: 65 | G416: 135 | H416: =E416*G416-D416*F416 -> 20300
B417: =RAND() -> 0.76222709 | C417: =_xlfn.FLOOR.MATH(_xlfn.NORM.INV(B417,$B$6,$B$7)) -> 365 | D417: =$B$9 -> 290 | E417: =_xlfn.FLOOR.MATH(MIN(C417,D417)) -> 290 | F417: 65 | G417: 135 | H417: =E417*G417-D417*F417 -> 20300
B418: =RAND() -> 0.58840857 | C418: =_xlfn.FLOOR.MATH(_xlfn.NORM.INV(B418,$B$6,$B$7)) -> 313 | D418: =$B$9 -> 290 | E418: =_xlfn.FLOOR.MATH(MIN(C418,D418)) -> 290 | F418: 65 | G418: 135 | H418: =E418*G418-D418*F418 -> 20300
B419: =RAND() -> 0.3714889 | C419: =_xlfn.FLOOR.MATH(_xlfn.NORM.INV(B419,$B$6,$B$7)) -> 255 | D419: =$B$9 -> 290 | E419: =_xlfn.FLOOR.MATH(MIN(C419,D419)) -> 255 | F419: 65 | G419: 135 | H419: =E419*G419-D419*F419 -> 15575
B420: =RAND() -> 0.31682435 | C420: =_xlfn.FLOOR.MATH(_xlfn.NORM.INV(B420,$B$6,$B$7)) -> 239 | D420: =$B$9 -> 290 | E420: =_xlfn.FLOOR.MATH(MIN(C420,D420)) -> 239 | F420: 65 | G420: 135 | H420: =E420*G420-D420*F420 -> 13415
B421: =RAND() -> 0.6110294 | C421: =_xlfn.FLOOR.MATH(_xlfn.NORM.INV(B421,$B$6,$B$7)) -> 319 | D421: =$B$9 -> 290 | E421: =_xlfn.FLOOR.MATH(MIN(C421,D421)) -> 290 | F421: 65 | G421: 135 | H421: =E421*G421-D421*F421 -> 20300
B422: =RAND() -> 0.77561854 | C422: =_xlfn.FLOOR.MATH(_xlfn.NORM.INV(B422,$B$6,$B$7)) -> 370 | D422: =$B$9 -> 290 | E422: =_xlfn.FLOOR.MATH(MIN(C422,D422)) -> 290 | F422: 65 | G422: 135 | H422: =E422*G422-D422*F422 -> 20300
B423: =RAND() -> 0.2315926 | C423: =_xlfn.FLOOR.MATH(_xlfn.NORM.INV(B423,$B$6,$B$7)) -> 212 | D423: =$B$9 -> 290 | E423: =_xlfn.FLOOR.MATH(MIN(C423,D423)) -> 212 | F423: 65 | G423: 135 | H423: =E423*G423-D423*F423 -> 9770
B424: =RAND() -> 0.81372567 | C424: =_xlfn.FLOOR.MATH(_xlfn.NORM.INV(B424,$B$6,$B$7)) -> 384 | D424: =$B$9 -> 290 | E424: =_xlfn.FLOOR.MATH(MIN(C424,D424)) -> 290 | F424: 65 | G424: 135 | H424: =E424*G424-D424*F424 -> 20300
B425: =RAND() -> 0.51942056 | C425: =_xlfn.FLOOR.MATH(_xlfn.NORM.INV(B425,$B$6,$B$7)) -> 295 | D425: =$B$9 -> 290 | E425: =_xlfn.FLOOR.MATH(MIN(C425,D425)) -> 290 | F425: 65 | G425: 135 | H425: =E425*G425-D425*F425 -> 20300
B426: =RAND() -> 0.94483284 | C426: =_xlfn.FLOOR.MATH(_xlfn.NORM.INV(B426,$B$6,$B$7)) -> 459 | D426: =$B$9 -> 290 | E426: =_xlfn.FLOOR.MATH(MIN(C426,D426)) -> 290 | F426: 65 | G426: 135 | H426: =E426*G426-D426*F426 -> 20300
B427: =RAND() -> 0.37608537 | C427: =_xlfn.FLOOR.MATH(_xlfn.NORM.INV(B427,$B$6,$B$7)) -> 256 | D427: =$B$9 -> 290 | E427: =_xlfn.FLOOR.MATH(MIN(C427,D427)) -> 256 | F427: 65 | G427: 135 | H427: =E427*G427-D427*F427 -> 15710
... B1000: =RAND() -> 0.061485104 | C1000: =_xlfn.FLOOR.MATH(_xlfn.NORM.INV(B1000,$B$6,$B$7)) -> 126 | D1000: =$B$9 -> 290 | E1000: =_xlfn.FLOOR.MATH(MIN(C1000,D1000)) -> 126 | F1000: 65 | G1000: 135 | H1000: =E1000*G1000-D1000*F1000 -> -1840

Sheet Task 5
A1: Cost Local | B1: 95
A2: Cost Ukraine | B2: 65
A3: Price | B3: 135
A4: LEC 24 Expected | B4: ='Task 3'!B6 -> 290.08236 | P4: OUTSOURCING | AG4: NEARSOURCING
A5: Std. Dev. LEC 24 | B5: ='Task 3'!B7 -> 105.97785
P6: Best Profit | Q6: =MAX(Q11:Q69) -> 9364.8358 | R6: =MAX(R11:R69) -> 10880.866 | S6: =MAX(S11:S69) -> 17554.448 | T6: =MAX(T11:T69) -> 11234.015 | U6: =MAX(U11:U69) -> 12950.269 | V6: =MAX(V11:V69) -> 9202.597 | W6: =MAX(W11:W69) -> 67695.269 | X6: =MAX(X11:X69) -> 67420.299 | ... AC6: =MAX(AC11:AC69) -> 8148.6866 | AG6: Best Profit | AH6: =MAX(AH11:AH69) -> 10994.542 | AI6: =MAX(AI11:AI69) -> 12878.975 | AJ6: =MAX(AJ11:AJ69) -> 19469.632 | AK6: =MAX(AK11:AK69) -> 13165.209 | AL6: =MAX(AL11:AL69) -> 14290.124 | AM6: =MAX(AM11:AM69) -> 11264.368 | AN6: =MAX(AN11:AN69) -> 69634.692 | AO6: =MAX(AO11:AO69) -> 69129.562 | ... AT6: =MAX(AT11:AT69) -> 10280.716
D7: Order Size (outsoursing) | E7: Avg. Profit (Outsourcing) | F7: Avg. Profit (Near-sourcing) | G7: Best Profit | H7: Best Order Size | P7: Best Order Size | Q7: =_xlfn.SINGLE(_xlfn.XLOOKUP(Q6,Q11:Q69,$AG$11:$AG$69,0,0,1)) -> 225 | R7: =_xlfn.SINGLE(_xlfn.XLOOKUP(R6,R11:R69,$AG$11:$AG$69,0,0,1)) -> 225 | S7: =_xlfn.SINGLE(_xlfn.XLOOKUP(S6,S11:S69,$AG$11:$AG$69,0,0,1)) -> 325 | T7: =_xlfn.SINGLE(_xlfn.XLOOKUP(T6,T11:T69,$AG$11:$AG$69,0,0,1)) -> 225 | U7: =_xlfn.SINGLE(_xlfn.XLOOKUP(U6,U11:U69,$AG$11:$AG$69,0,0,1)) -> 275 | V7: =_xlfn.SINGLE(_xlfn.XLOOKUP(V6,V11:V69,$AG$11:$AG$69,0,0,1)) -> 200 | W7: =_xlfn.SINGLE(_xlfn.XLOOKUP(W6,W11:W69,$AG$11:$AG$69,0,0,1)) -> 1050 | X7: =_xlfn.SINGLE(_xlfn.XLOOKUP(X6,X11:X69,$AG$11:$AG$69,0,0,1)) -> 1050 | ... AC7: =_xlfn.SINGLE(_xlfn.XLOOKUP(AC6,AC11:AC69,$AG$11:$AG$69,0,0,1)) -> 175 | AG7: Best Order Size | AH7: =_xlfn.SINGLE(_xlfn.XLOOKUP(AH6,AH11:AH69,$AG$11:$AG$69,0,0,1)) -> 175 | AI7: =_xlfn.SINGLE(_xlfn.XLOOKUP(AI6,AI11:AI69,$AG$11:$AG$69,0,0,1)) -> 225 | AJ7: =_xlfn.SINGLE(_xlfn.XLOOKUP(AJ6,AJ11:AJ69,$AG$11:$AG$69,0,0,1)) -> 300 | AK7: =_xlfn.SINGLE(_xlfn.XLOOKUP(AK6,AK11:AK69,$AG$11:$AG$69,0,0,1)) -> 200 | AL7: =_xlfn.SINGLE(_xlfn.XLOOKUP(AL6,AL11:AL69,$AG$11:$AG$69,0,0,1)) -> 225 | AM7: =_xlfn.SINGLE(_xlfn.XLOOKUP(AM6,AM11:AM69,$AG$11:$AG$69,0,0,1)) -> 150 | AN7: =_xlfn.SINGLE(_xlfn.XLOOKUP(AN6,AN11:AN69,$AG$11:$AG$69,0,0,1)) -> 1000 | AO7: =_xlfn.SINGLE(_xlfn.XLOOKUP(AO6,AO11:AO69,$AG$11:$AG$69,0,0,1)) -> 1025 | ... AT7: =_xlfn.SINGLE(_xlfn.XLOOKUP(AT6,AT11:AT69,$AG$11:$AG$69,0,0,1)) -> 175
D8: 300 | E8: =AVERAGE(D12:D1016) -> 14402.463 | F8: =AVERAGE(I12:I1016) -> 15781.129 | G8: =MAX(L11:L71) -> 16840.786 | H8: =_xlfn.XLOOKUP(G8,L11:L71,K11:K71,0,0,1) -> 260 | P8: Order Size | Q8: LEC 11 | R8: LEC 12 | S8: LEC 13 | T8: LEC 14 | U8: LEC 15 | V8: LEC 16 | W8: LEC 17 | X8: LEC 18 | Y8: LEC 19 | Z8: LEC 20 | AA8: LEC 21 | AB8: LEC 22 | AC8: LEC 23 | AG8: Order Size | AH8: LEC 11 | AI8: LEC 12 | AJ8: LEC 13 | AK8: LEC 14 | AL8: LEC 15 | AM8: LEC 16 | AN8: LEC 17 | AO8: LEC 18 | AP8: LEC 19 | AQ8: LEC 20 | AR8: LEC 21 | AS8: LEC 22 | AT8: LEC 23
K9: Order Size | L9: Avg. Profit
L10: =F8 -> 15781.129 | O10: Forecast Demand | P10: =AVERAGE(D12:D1016) -> 14402.463 | Q10: {=TRANSPOSE('Task 6'!M2:M14)} -> 213.05229 | R10: 238.42052 | S10: 330.65706 | T10: 238.42052 | U10: 260.79688 | V10: 213.05229 | W10: 1047.6988 | X10: 1042.3469 | Y10: 999.95423 | Z10: 249.93796 | AA10: 167.23644 | AB10: 213.05229 | AC10: 198.97329 | AF10: Forecast Demand | AG10: =F8 -> 15781.129 | AH10: {=TRANSPOSE('Task 6'!M2:M14)} -> 213.05229 | AI10: 238.42052 | AJ10: 330.65706 | AK10: 238.42052 | AL10: 260.79688 | AM10: 213.05229 | AN10: 1047.6988 | AO10: 1042.3469 | AP10: 999.95423 | AQ10: 249.93796 | AR10: 167.23644 | AS10: 213.05229 | AT10: 198.97329
B11: Demand | C11: Sales (outsoursing) | D11: Profit (outsoursing) | E11: Extra demand | F11: Local capacity | G11: Local quantity | H11: Total sales | I11: Profit (nearsoursing) | K11: 100 | L11: 12246.567 | P11: 50 | Q11: 3201.9254 | R11: 3262.9104 | S11: 3475.1493 | T11: 3178.1493 | U11: 3360.2985 | V11: 3100.6418 | W11: 3500 | X11: 3500 | Y11: 3500 | Z11: 3360.5672 | AA11: 2571.5224 | AB11: 3182.9851 | AC11: 3043.6866 | AG11: 50 | AH11: 8271.0398 | AI11: 8801.6866 | AJ11: 9842.3284 | AK11: 8643.7811 | AL11: 9134.4975 | AM11: 8349.01 | AN11: 10220 | AO11: 10220 | AP11: 10220 | AQ11: 9015.0647 | AR11: 6545.7711 | AS11: 8326.7363 | AT11: 7548.9701
B12: =_xlfn.FLOOR.MATH(_xlfn.NORM.INV(RAND(),$B$4,$B$5)) -> 200 | C12: =MIN(B12,$D$8) -> 200 | D12: =C12*$B$3-$D$8*$B$2 -> 7500 | E12: =MAX(0, B12-$D$8) -> 0 | F12: =12*(21-7) -> 168 | G12: =MIN(E12,F12) -> 0 | H12: =MIN(B12, $D$8+G12) -> 200 | I12: =H12*$B$3-$D$8*$B$2-$B$1*G12 -> 7500 | K12: 110 | L12: 12661.209 | P12: 75 | Q12: 4805.5075 | R12: 4856.8209 | S12: 5221.791 | T12: 4782.403 | U12: 4889.4627 | V12: 4622.9552 | W12: 5250 | X12: 5250 | Y12: 5250 | Z12: 4997.597 | AA12: 3696.8955 | AB12: 4482.5821 | AC12: 4395.806 | AG12: 75 | AH12: 9160.7214 | AI12: 9987.9502 | AJ12: 11466.532 | AK12: 9844.6965 | AL12: 10571.164 | AM12: 8969.8856 | AN12: 11970 | AO12: 11970 | AP12: 11970 | AQ12: 10264.498 | AR12: 7669.2537 | AS12: 9281.1443 | AT12: 8633.4826
B13: =_xlfn.FLOOR.MATH(_xlfn.NORM.INV(RAND(),$B$4,$B$5)) -> 291 | C13: =MIN(B13,$D$8) -> 291 | D13: =C13*$B$3-$D$8*$B$2 -> 19785 | E13: =MAX(0, B13-$D$8) -> 0 | F13: =12*(21-7) -> 168 | G13: =MIN(E13,F13) -> 0 | H13: =MIN(B13, $D$8+G13) -> 291 | I13: =H13*$B$3-$D$8*$B$2-$B$1*G13 -> 19785 | K13: 120 | L13: 13088.478 | P13: 100 | Q13: 5782.0448 | R13: 6438.6418 | S13: 6934.5821 | T13: 6383.5672 | U13: 6538.3134 | V13: 5756.1194 | W13: 7000 | X13: 7000 | Y13: 7000 | Z13: 6338.9701 | AA13: 4660.403 | AB13: 6037.9403 | AC13: 5488 | AG13: 100 | AH13: 9908.199 | AI13: 10697.502 | AJ13: 12901.652 | AK13: 10697.433 | AL13: 11671.448 | AM13: 10190.861 | AN13: 13720 | AO13: 13720 | AP13: 13720 | AQ13: 11473.98 | AR13: 7309.4726 | AS13: 10113.9 | AT13: 9193.8358
B14: =_xlfn.FLOOR.MATH(_xlfn.NORM.INV(RAND(),$B$4,$B$5)) -> 489 | C14: =MIN(B14,$D$8) -> 300 | D14: =C14*$B$3-$D$8*$B$2 -> 21000 | E14: =MAX(0, B14-$D$8) -> 189 | F14: =12*(21-7) -> 168 | G14: =MIN(E14,F14) -> 168 | H14: =MIN(B14, $D$8+G14) -> 468 | I14: =H14*$B$3-$D$8*$B$2-$B$1*G14 -> 27720 | K14: 130 | L14: 13766.413 | P14: 125 | Q14: 7227.1194 | R14: 7622.7164 | S14: 8558.3134 | T14: 7673.0896 | U14: 7859.1343 | V14: 7199.9851 | W14: 8750 | X14: 8750 | Y14: 8750 | Z14: 7710.0299 | AA14: 5006.5373 | AB14: 6835.6866 | AC14: 6672.7463 | AG14: 125 | AH14: 10650.488 | AI14: 11762.871 | AJ14: 14193.443 | AK14: 11660.577 | AL14: 12582.274 | AM14: 10530.289 | AN14: 15470 | AO14: 15470 | AP14: 15470 | AQ14: 11880.343 | AR14: 8244.1244 | AS14: 10422.647 | AT14: 9730.6567
B15: =_xlfn.FLOOR.MATH(_xlfn.NORM.INV(RAND(),$B$4,$B$5)) -> 124 | C15: =MIN(B15,$D$8) -> 124 | D15: =C15*$B$3-$D$8*$B$2 -> -2760 | E15: =MAX(0, B15-$D$8) -> 0 | F15: =12*(21-7) -> 168 | G15: =MIN(E15,F15) -> 0 | H15: =MIN(B15, $D$8+G15) -> 124 | I15: =H15*$B$3-$D$8*$B$2-$B$1*G15 -> -2760 | K15: 140 | L15: 13871.955 | P15: 150 | Q15: 7868.3731 | R15: 8926.0746 | S15: 10279.567 | T15: 8773.7463 | U15: 9351.4925 | V15: 8099.9552 | W15: 10500 | X15: 10500 | Y15: 10500 | Z15: 9191.5075 | AA15: 5789.1045 | AB15: 8393.597 | AC15: 7801.0746 | AG15: 150 | AH15: 10902.9 | AI15: 12463.896 | AJ15: 15612.169 | AK15: 12332.662 | AL15: 13819.493 | AM15: 11264.368 | AN15: 17220 | AO15: 17220 | AP15: 17220 | AQ15: 13253.96 | AR15: 7441.8458 | AS15: 10897.224 | AT15: 9930.7015
B16: =_xlfn.FLOOR.MATH(_xlfn.NORM.INV(RAND(),$B$4,$B$5)) -> 295 | C16: =MIN(B16,$D$8) -> 295 | D16: =C16*$B$3-$D$8*$B$2 -> 20325 | E16: =MAX(0, B16-$D$8) -> 0 | F16: =12*(21-7) -> 168 | G16: =MIN(E16,F16) -> 0 | H16: =MIN(B16, $D$8+G16) -> 295 | I16: =H16*$B$3-$D$8*$B$2-$B$1*G16 -> 20325 | K16: 150 | L16: 14560.104 | P16: 175 | Q16: 8744.5672 | R16: 9623.209 | S16: 11883.687 | T16: 10003.224 | U16: 10596.552 | V16: 8678.7463 | W16: 12250 | X16: 12250 | Y16: 12250 | Z16: 10504.269 | AA16: 6403.8955 | AB16: 8572.8955 | AC16: 8148.6866 | AG16: 175 | AH16: 10994.542 | AI16: 12757.915 | AJ16: 16684.104 | AK16: 12783.095 | AL16: 14169.04 | AM16: 10952.836 | AN16: 18970 | AO16: 18970 | AP16: 18970 | AQ16: 13495.453 | AR16: 8038.5423 | AS16: 11321.035 | AT16: 10280.716
B17: =_xlfn.FLOOR.MATH(_xlfn.NORM.INV(RAND(),$B$4,$B$5)) -> 414 | C17: =MIN(B17,$D$8) -> 300 | D17: =C17*$B$3-$D$8*$B$2 -> 21000 | E17: =MAX(0, B17-$D$8) -> 114 | F17: =12*(21-7) -> 168 | G17: =MIN(E17,F17) -> 114 | H17: =MIN(B17, $D$8+G17) -> 414 | I17: =H17*$B$3-$D$8*$B$2-$B$1*G17 -> 25560 | K17: 160 | L17: 14849.463 | P17: 200 | Q17: 9129.6567 | R17: 10523.448 | S17: 13245.881 | T17: 10259.224 | U17: 11564.896 | V17: 9202.597 | W17: 14000 | X17: 14000 | Y17: 14000 | Z17: 11033.761 | AA17: 6292.5075 | AB17: 9126.4328 | AC17: 7896.5224 | AG17: 200 | AH17: 10628.587 | AI17: 12543.134 | AJ17: 17800.224 | AK17: 13165.209 | AL17: 14090.567 | AM17: 10930.891 | AN17: 20720 | AO17: 20720 | AP17: 20720 | AQ17: 13397.239 | AR17: 6846.2786 | AS17: 10810.229 | AT17: 9947.6816
B18: =_xlfn.FLOOR.MATH(_xlfn.NORM.INV(RAND(),$B$4,$B$5)) -> 354 | C18: =MIN(B18,$D$8) -> 300 | D18: =C18*$B$3-$D$8*$B$2 -> 21000 | E18: =MAX(0, B18-$D$8) -> 54 | F18: =12*(21-7) -> 168 | G18: =MIN(E18,F18) -> 54 | H18: =MIN(B18, $D$8+G18) -> 354 | I18: =H18*$B$3-$D$8*$B$2-$B$1*G18 -> 23160 | K18: 170 | L18: 14967.035 | P18: 225 | Q18: 9364.8358 | R18: 10880.866 | S18: 14448.358 | T18: 11234.015 | U18: 12137.104 | V18: 9183.2239 | W18: 15750 | X18: 15750 | Y18: 15750 | Z18: 11578.701 | AA18: 5049.806 | AB18: 9460.6119 | AC18: 7850.2836 | AG18: 225 | AH18: 10455.299 | AI18: 12878.975 | AJ18: 18170.93 | AK18: 12567.662 | AL18: 14290.124 | AM18: 10879.925 | AN18: 22470 | AO18: 22470 | AP18: 22470 | AQ18: 13591.308 | AR18: 6305.3234 | AS18: 10576.488 | AT18: 9285.1592
B19: =_xlfn.FLOOR.MATH(_xlfn.NORM.INV(RAND(),$B$4,$B$5)) -> 273 | C19: =MIN(B19,$D$8) -> 273 | D19: =C19*$B$3-$D$8*$B$2 -> 17355 | E19: =MAX(0, B19-$D$8) -> 0 | F19: =12*(21-7) -> 168 | G19: =MIN(E19,F19) -> 0 | H19: =MIN(B19, $D$8+G19) -> 273 | I19: =H19*$B$3-$D$8*$B$2-$B$1*G19 -> 17355 | K19: 180 | L19: 15547.532 | P19: 250 | Q19: 8790.6866 | R19: 10837.313 | S19: 15545.791 | T19: 10777.537 | U19: 12586.806 | V19: 8389.5821 | W19: 17500 | X19: 17500 | Y19: 17500 | Z19: 11562.552 | AA19: 4274.7015 | AB19: 8846.8358 | AC19: 7773.0149 | AG19: 250 | AH19: 10430.841 | AI19: 12273.94 | AJ19: 18916.289 | AK19: 12008.786 | AL19: 14088.08 | AM19: 10186.214 | AN19: 24220 | AO19: 24220 | AP19: 24220 | AQ19: 13609.567 | AR19: 5415.4179 | AS19: 10183.761 | AT19: 8524.209
B20: =_xlfn.FLOOR.MATH(_xlfn.NORM.INV(RAND(),$B$4,$B$5)) -> 27 | C20: =MIN(B20,$D$8) -> 27 | D20: =C20*$B$3-$D$8*$B$2 -> -15855 | E20: =MAX(0, B20-$D$8) -> 0 | F20: =12*(21-7) -> 168 | G20: =MIN(E20,F20) -> 0 | H20: =MIN(B20, $D$8+G20) -> 27 | I20: =H20*$B$3-$D$8*$B$2-$B$1*G20 -> -15855 | K20: 190 | L20: 15878.139 | P20: 275 | Q20: 7805.4925 | R20: 10713.567 | S20: 16646.045 | T20: 10275.522 | U20: 12950.269 | V20: 8420.1791 | W20: 19250 | X20: 19250 | Y20: 19250 | Z20: 11395.552 | AA20: 3223.0149 | AB20: 8636.9851 | AC20: 7238.3582 | AG20: 275 | AH20: 8893.4577 | AI20: 11990.139 | AJ20: 18735.09 | AK20: 12162.05 | AL20: 13837.03 | AM20: 9135.8308 | AN20: 25970 | AO20: 25970 | AP20: 25970 | AQ20: 12949.448 | AR20: 4674.204 | AS20: 9265.5423 | AT20: 7457.9104
B21: =_xlfn.FLOOR.MATH(_xlfn.NORM.INV(RAND(),$B$4,$B$5)) -> 392 | C21: =MIN(B21,$D$8) -> 300 | D21: =C21*$B$3-$D$8*$B$2 -> 21000 | E21: =MAX(0, B21-$D$8) -> 92 | F21: =12*(21-7) -> 168 | G21: =MIN(E21,F21) -> 92 | H21: =MIN(B21, $D$8+G21) -> 392 | I21: =H21*$B$3-$D$8*$B$2-$B$1*G21 -> 24680 | K21: 200 | L21: 15915.761 | P21: 300 | Q21: 7747.1642 | R21: 10110.134 | S21: 17389.522 | T21: 9860.9552 | U21: 11649.403 | V21: 7788.6716 | W21: 21000 | X21: 21000 | Y21: 21000 | Z21: 10885.343 | AA21: 1941.6269 | AB21: 7527.806 | AC21: 5528.194 | AG21: 300 | AH21: 7862.2388 | AI21: 11643.886 | AJ21: 19469.632 | AK21: 11491.975 | AL21: 13324.09 | AM21: 7914.0448 | AN21: 27720 | AO21: 27720 | AP21: 27720 | AQ21: 11499.871 | AR21: 2290.2687 | AS21: 8073.2139 | AT21: 7123.592
B22: =_xlfn.FLOOR.MATH(_xlfn.NORM.INV(RAND(),$B$4,$B$5)) -> 251 | C22: =MIN(B22,$D$8) -> 251 | D22: =C22*$B$3-$D$8*$B$2 -> 14385 | E22: =MAX(0, B22-$D$8) -> 0 | F22: =12*(21-7) -> 168 | G22: =MIN(E22,F22) -> 0 | H22: =MIN(B22, $D$8+G22) -> 251 | I22: =H22*$B$3-$D$8*$B$2-$B$1*G22 -> 14385 | K22: 210 | L22: 16332.338 | P22: 325 | Q22: 6613.5373 | R22: 8736.7313 | S22: 17554.448 | T22: 9649.0896 | U22: 11856.239 | V22: 6277.5821 | W22: 22750 | X22: 22750 | Y22: 22750 | Z22: 10135.09 | AA22: 1328.9254 | AB22: 7224.4627 | AC22: 4728.1045 | AG22: 325 | AH22: 7017.0498 | AI22: 10172.249 | AJ22: 18878.294 | AK22: 9415.4328 | AL22: 12825.602 | AM22: 6389.199 | AN22: 29470 | AO22: 29470 | AP22: 29470 | AQ22: 11710.826 | AR22: 1031.2786 | AS22: 6745.4826 | AT22: 5683.6816
B23: =_xlfn.FLOOR.MATH(_xlfn.NORM.INV(RAND(),$B$4,$B$5)) -> 127 | C23: =MIN(B23,$D$8) -> 127 | D23: =C23*$B$3-$D$8*$B$2 -> -2355 | E23: =MAX(0, B23-$D$8) -> 0 | F23: =12*(21-7) -> 168 | G23: =MIN(E23,F23) -> 0 | H23: =MIN(B23, $D$8+G23) -> 127 | I23: =H23*$B$3-$D$8*$B$2-$B$1*G23 -> -2355 | K23: 220 | L23: 16242.761 | P23: 350 | Q23: 6386.7612 | R23: 8637.4328 | S23: 17172.119 | T23: 7841.806 | U23: 10912.015 | V23: 5612.0896 | W23: 24500 | X23: 24500 | Y23: 24500 | Z23: 10086.701 | AA23: -795.23881 | AB23: 5390.9851 | AC23: 3867.7015 | AG23: 350 | AH23: 5635.4478 | AI23: 8728.2338 | AJ23: 18456.139 | AK23: 9083.5622 | AL23: 10885.577 | AM23: 5700.8159 | AN23: 31220 | AO23: 31220 | AP23: 31220 | AQ23: 9672.2836 | AR23: -1140.5771 | AS23: 5510.3881 | AT23: 3149.801
... B69: =_xlfn.FLOOR.MATH(_xlfn.NORM.INV(RAND(),$B$4,$B$5)) -> 316 | C69: =MIN(B69,$D$8) -> 300 | D69: =C69*$B$3-$D$8*$B$2 -> 21000 | E69: =MAX(0, B69-$D$8) -> 16 | F69: =12*(21-7) -> 168 | G69: =MIN(E69,F69) -> 16 | H69: =MIN(B69, $D$8+G69) -> 316 | I69: =H69*$B$3-$D$8*$B$2-$B$1*G69 -> 21640 | K69: 680 | L69: -4887.0597 | P69: 1500 | Q69: -68555.06 | R69: -65737.254 | S69: -53405.642 | T69: -64683.179 | U69: -62001.448 | V69: -68562.313 | W69: 44184.985 | X69: 42538.925 | Y69: 37277.284 | Z69: -64621.388 | AA69: -74948.821 | AB69: -68614.567 | AC69: -70425.716 | AG69: 1500 | AH69: -68641.433 | AI69: -65606.821 | AJ69: -52841.866 | AK69: -65474.239 | AL69: -62266.478 | AM69: -68543.776 | AN69: 43488.09 | AO69: 43344.761 | AP69: 38313.358 | AQ69: -64024.299 | AR69: -74894.015 | AS69: -69378.224 | AT69: -70930.254
B70: =_xlfn.FLOOR.MATH(_xlfn.NORM.INV(RAND(),$B$4,$B$5)) -> 144 | C70: =MIN(B70,$D$8) -> 144 | D70: =C70*$B$3-$D$8*$B$2 -> -60 | E70: =MAX(0, B70-$D$8) -> 0 | F70: =12*(21-7) -> 168 | G70: =MIN(E70,F70) -> 0 | H70: =MIN(B70, $D$8+G70) -> 144 | I70: =H70*$B$3-$D$8*$B$2-$B$1*G70 -> -60 | K70: 690 | L70: -5811.6269
B71: =_xlfn.FLOOR.MATH(_xlfn.NORM.INV(RAND(),$B$4,$B$5)) -> 116 | C71: =MIN(B71,$D$8) -> 116 | D71: =C71*$B$3-$D$8*$B$2 -> -3840 | E71: =MAX(0, B71-$D$8) -> 0 | F71: =12*(21-7) -> 168 | G71: =MIN(E71,F71) -> 0 | H71: =MIN(B71, $D$8+G71) -> 116 | I71: =H71*$B$3-$D$8*$B$2-$B$1*G71 -> -3840 | K71: 700 | L71: -6213.1194
B72: =_xlfn.FLOOR.MATH(_xlfn.NORM.INV(RAND(),$B$4,$B$5)) -> 189 | C72: =MIN(B72,$D$8) -> 189 | D72: =C72*$B$3-$D$8*$B$2 -> 6015 | E72: =MAX(0, B72-$D$8) -> 0 | F72: =12*(21-7) -> 168 | G72: =MIN(E72,F72) -> 0 | H72: =MIN(B72, $D$8+G72) -> 189 | I72: =H72*$B$3-$D$8*$B$2-$B$1*G72 -> 6015
B73: =_xlfn.FLOOR.MATH(_xlfn.NORM.INV(RAND(),$B$4,$B$5)) -> 215 | C73: =MIN(B73,$D$8) -> 215 | D73: =C73*$B$3-$D$8*$B$2 -> 9525 | E73: =MAX(0, B73-$D$8) -> 0 | F73: =12*(21-7) -> 168 | G73: =MIN(E73,F73) -> 0 | H73: =MIN(B73, $D$8+G73) -> 215 | I73: =H73*$B$3-$D$8*$B$2-$B$1*G73 -> 9525
B74: =_xlfn.FLOOR.MATH(_xlfn.NORM.INV(RAND(),$B$4,$B$5)) -> 345 | C74: =MIN(B74,$D$8) -> 300 | D74: =C74*$B$3-$D$8*$B$2 -> 21000 | E74: =MAX(0, B74-$D$8) -> 45 | F74: =12*(21-7) -> 168 | G74: =MIN(E74,F74) -> 45 | H74: =MIN(B74, $D$8+G74) -> 345 | I74: =H74*$B$3-$D$8*$B$2-$B$1*G74 -> 22800
B75: =_xlfn.FLOOR.MATH(_xlfn.NORM.INV(RAND(),$B$4,$B$5)) -> 188 | C75: =MIN(B75,$D$8) -> 188 | D75: =C75*$B$3-$D$8*$B$2 -> 5880 | E75: =MAX(0, B75-$D$8) -> 0 | F75: =12*(21-7) -> 168 | G75: =MIN(E75,F75) -> 0 | H75: =MIN(B75, $D$8+G75) -> 188 | I75: =H75*$B$3-$D$8*$B$2-$B$1*G75 -> 5880
B76: =_xlfn.FLOOR.MATH(_xlfn.NORM.INV(RAND(),$B$4,$B$5)) -> 342 | C76: =MIN(B76,$D$8) -> 300 | D76: =C76*$B$3-$D$8*$B$2 -> 21000 | E76: =MAX(0, B76-$D$8) -> 42 | F76: =12*(21-7) -> 168 | G76: =MIN(E76,F76) -> 42 | H76: =MIN(B76, $D$8+G76) -> 342 | I76: =H76*$B$3-$D$8*$B$2-$B$1*G76 -> 22680
B77: =_xlfn.FLOOR.MATH(_xlfn.NORM.INV(RAND(),$B$4,$B$5)) -> 202 | C77: =MIN(B77,$D$8) -> 202 | D77: =C77*$B$3-$D$8*$B$2 -> 7770 | E77: =MAX(0, B77-$D$8) -> 0 | F77: =12*(21-7) -> 168 | G77: =MIN(E77,F77) -> 0 | H77: =MIN(B77, $D$8+G77) -> 202 | I77: =H77*$B$3-$D$8*$B$2-$B$1*G77 -> 7770
B78: =_xlfn.FLOOR.MATH(_xlfn.NORM.INV(RAND(),$B$4,$B$5)) -> 363 | C78: =MIN(B78,$D$8) -> 300 | D78: =C78*$B$3-$D$8*$B$2 -> 21000 | E78: =MAX(0, B78-$D$8) -> 63 | F78: =12*(21-7) -> 168 | G78: =MIN(E78,F78) -> 63 | H78: =MIN(B78, $D$8+G78) -> 363 | I78: =H78*$B$3-$D$8*$B$2-$B$1*G78 -> 23520
B79: =_xlfn.FLOOR.MATH(_xlfn.NORM.INV(RAND(),$B$4,$B$5)) -> 210 | C79: =MIN(B79,$D$8) -> 210 | D79: =C79*$B$3-$D$8*$B$2 -> 8850 | E79: =MAX(0, B79-$D$8) -> 0 | F79: =12*(21-7) -> 168 | G79: =MIN(E79,F79) -> 0 | H79: =MIN(B79, $D$8+G79) -> 210 | I79: =H79*$B$3-$D$8*$B$2-$B$1*G79 -> 8850
B80: =_xlfn.FLOOR.MATH(_xlfn.NORM.INV(RAND(),$B$4,$B$5)) -> 348 | C80: =MIN(B80,$D$8) -> 300 | D80: =C80*$B$3-$D$8*$B$2 -> 21000 | E80: =MAX(0, B80-$D$8) -> 48 | F80: =12*(21-7) -> 168 | G80: =MIN(E80,F80) -> 48 | H80: =MIN(B80, $D$8+G80) -> 348 | I80: =H80*$B$3-$D$8*$B$2-$B$1*G80 -> 22920
B81: =_xlfn.FLOOR.MATH(_xlfn.NORM.INV(RAND(),$B$4,$B$5)) -> 195 | C81: =MIN(B81,$D$8) -> 195 | D81: =C81*$B$3-$D$8*$B$2 -> 6825 | E81: =MAX(0, B81-$D$8) -> 0 | F81: =12*(21-7) -> 168 | G81: =MIN(E81,F81) -> 0 | H81: =MIN(B81, $D$8+G81) -> 195 | I81: =H81*$B$3-$D$8*$B$2-$B$1*G81 -> 6825
B82: =_xlfn.FLOOR.MATH(_xlfn.NORM.INV(RAND(),$B$4,$B$5)) -> 105 | C82: =MIN(B82,$D$8) -> 105 | D82: =C82*$B$3-$D$8*$B$2 -> -5325 | E82: =MAX(0, B82-$D$8) -> 0 | F82: =12*(21-7) -> 168 | G82: =MIN(E82,F82) -> 0 | H82: =MIN(B82, $D$8+G82) -> 105 | I82: =H82*$B$3-$D$8*$B$2-$B$1*G82 -> -5325
B83: =_xlfn.FLOOR.MATH(_xlfn.NORM.INV(RAND(),$B$4,$B$5)) -> 369 | C83: =MIN(B83,$D$8) -> 300 | D83: =C83*$B$3-$D$8*$B$2 -> 21000 | E83: =MAX(0, B83-$D$8) -> 69 | F83: =12*(21-7) -> 168 | G83: =MIN(E83,F83) -> 69 | H83: =MIN(B83, $D$8+G83) -> 369 | I83: =H83*$B$3-$D$8*$B$2-$B$1*G83 -> 23760
... B1016: =_xlfn.FLOOR.MATH(_xlfn.NORM.INV(RAND(),$B$4,$B$5)) -> 362 | C1016: =MIN(B1016,$D$8) -> 300 | D1016: =C1016*$B$3-$D$8*$B$2 -> 21000 | E1016: =MAX(0, B1016-$D$8) -> 62 | F1016: =12*(21-7) -> 168 | G1016: =MIN(E1016,F1016) -> 62 | H1016: =MIN(B1016, $D$8+G1016) -> 362 | I1016: =H1016*$B$3-$D$8*$B$2-$B$1*G1016 -> 23480

Sheet Task 6
H1: LEC ID | I1: Length | J1: Std. Ln(Len) | K1: Contains Holiday | L1: Actual demand | M1: Forecast demand | N1: optimal quantity | O1: Sales | P1: profit
A2: Cost Local | B2: 95 | H2: 11 | I2: =Regression!B12 -> 14 | J2: =(LN(I2)-Regression!$B$26)/Regression!$B$27 -> -0.63567925 | K2: 0 | L2: =Regression!F12 -> 153 | M2: =Regression!$I$20+J2*Regression!$I$21+K2*Regression!$I$22 -> 213.05229 | N2: {=TRANSPOSE('Task 5'!Q7:AC7)} -> 225 | O2: =MIN(L2,N2) -> 153 | P2: =$B$4*O2-$B$3*N2 -> 6030
A3: Cost Ukraine | B3: 65 | H3: =H2+1 -> 12 | I3: =Regression!B13 -> 16 | J3: =(LN(I3)-Regression!$B$26)/Regression!$B$27 -> -0.22271672 | K3: 0 | L3: =Regression!F13 -> 322 | M3: =Regression!$I$20+J3*Regression!$I$21+K3*Regression!$I$22 -> 238.42052 | N3: 225 | O3: =MIN(L3,N3) -> 225 | P3: =$B$4*O3-$B$3*N3 -> 15750
A4: Price | B4: 135 | H4: =H3+1 -> 13 | I4: =Regression!B14 -> 26 | J4: =(LN(I4)-Regression!$B$26)/Regression!$B$27 -> 1.2787769 | K4: 0 | L4: =Regression!F14 -> 298 | M4: =Regression!$I$20+J4*Regression!$I$21+K4*Regression!$I$22 -> 330.65706 | N4: 325 | O4: =MIN(L4,N4) -> 298 | P4: =$B$4*O4-$B$3*N4 -> 19105
H5: =H4+1 -> 14 | I5: =Regression!B15 -> 16 | J5: =(LN(I5)-Regression!$B$26)/Regression!$B$27 -> -0.22271672 | K5: 0 | L5: =Regression!F15 -> 133 | M5: =Regression!$I$20+J5*Regression!$I$21+K5*Regression!$I$22 -> 238.42052 | N5: 225 | O5: =MIN(L5,N5) -> 133 | P5: =$B$4*O5-$B$3*N5 -> 3330
H6: =H5+1 -> 15 | I6: =Regression!B16 -> 18 | J6: =(LN(I6)-Regression!$B$26)/Regression!$B$27 -> 0.14154205 | K6: 0 | L6: =Regression!F16 -> 192 | M6: =Regression!$I$20+J6*Regression!$I$21+K6*Regression!$I$22 -> 260.79688 | N6: 275 | O6: =MIN(L6,N6) -> 192 | P6: =$B$4*O6-$B$3*N6 -> 8045
A7: LEC ID | B7: Profit outsoursing | C7: Profit near-soursing | D7: Benefit | H7: =H6+1 -> 16 | I7: =Regression!B17 -> 14 | J7: =(LN(I7)-Regression!$B$26)/Regression!$B$27 -> -0.63567925 | K7: 0 | L7: =Regression!F17 -> 198 | M7: =Regression!$I$20+J7*Regression!$I$21+K7*Regression!$I$22 -> 213.05229 | N7: 200 | O7: =MIN(L7,N7) -> 198 | P7: =$B$4*O7-$B$3*N7 -> 13730
A8: =Regression!A12 -> 11 | B8: =P2 -> 6030 | C8: =Q19 -> 12250 | D8: =C8-B8 -> 6220 | H8: =H7+1 -> 17 | I8: =Regression!B18 -> 36 | J8: =(LN(I8)-Regression!$B$26)/Regression!$B$27 -> 2.2851864 | K8: 1 | L8: =Regression!F18 -> 991 | M8: =Regression!$I$20+J8*Regression!$I$21+K8*Regression!$I$22 -> 1047.6988 | N8: 1050 | O8: =MIN(L8,N8) -> 991 | P8: =$B$4*O8-$B$3*N8 -> 65535
A9: =Regression!A13 -> 12 | B9: =P3 -> 15750 | C9: =Q20 -> 19630 | D9: =C9-B9 -> 3880 | H9: =H8+1 -> 18 | I9: =Regression!B19 -> 35 | J9: =(LN(I9)-Regression!$B$26)/Regression!$B$27 -> 2.1980644 | K9: 1 | L9: =Regression!F19 -> 1244 | M9: =Regression!$I$20+J9*Regression!$I$21+K9*Regression!$I$22 -> 1042.3469 | N9: 1050 | O9: =MIN(L9,N9) -> 1050 | P9: =$B$4*O9-$B$3*N9 -> 73500
A10: =Regression!A14 -> 13 | B10: =P4 -> 19105 | C10: =Q21 -> 21000 | D10: =C10-B10 -> 1895 | H10: =H9+1 -> 19 | I10: =Regression!B20 -> 28 | J10: =(LN(I10)-Regression!$B$26)/Regression!$B$27 -> 1.5079651 | K10: 1 | L10: =Regression!F20 -> 855 | M10: =Regression!$I$20+J10*Regression!$I$21+K10*Regression!$I$22 -> 999.95423 | N10: 1025 | O10: =MIN(L10,N10) -> 855 | P10: =$B$4*O10-$B$3*N10 -> 48800
A11: =Regression!A15 -> 14 | B11: =P5 -> 3330 | C11: =Q22 -> 14000 | D11: =C11-B11 -> 10670 | H11: =H10+1 -> 20 | I11: =Regression!B21 -> 17 | J11: =(LN(I11)-Regression!$B$26)/Regression!$B$27 -> -0.035227495 | K11: 0 | L11: =Regression!F21 -> 291 | M11: =Regression!$I$20+J11*Regression!$I$21+K11*Regression!$I$22 -> 249.93796 | N11: 225 | O11: =MIN(L11,N11) -> 225 | P11: =$B$4*O11-$B$3*N11 -> 15750
A12: =Regression!A16 -> 15 | B12: =P6 -> 8045 | C12: =Q23 -> 15750 | D12: =C12-B12 -> 7705 | H12: =H11+1 -> 21 | I12: =Regression!B22 -> 11 | J12: =(LN(I12)-Regression!$B$26)/Regression!$B$27 -> -1.3815031 | K12: 0 | L12: =Regression!F22 -> 143 | M12: =Regression!$I$20+J12*Regression!$I$21+K12*Regression!$I$22 -> 167.23644 | N12: 175 | O12: =MIN(L12,N12) -> 143 | P12: =$B$4*O12-$B$3*N12 -> 7930
A13: =Regression!A17 -> 16 | B13: =P7 -> 13730 | C13: =Q24 -> 12420 | D13: =C13-B13 -> -1310 | H13: =H12+1 -> 22 | I13: =Regression!B23 -> 14 | J13: =(LN(I13)-Regression!$B$26)/Regression!$B$27 -> -0.63567925 | K13: 0 | L13: =Regression!F23 -> 253 | M13: =Regression!$I$20+J13*Regression!$I$21+K13*Regression!$I$22 -> 213.05229 | N13: 225 | O13: =MIN(L13,N13) -> 225 | P13: =$B$4*O13-$B$3*N13 -> 15750
A14: =Regression!A18 -> 17 | B14: =P8 -> 65535 | C14: =Q25 -> 70000 | D14: =C14-B14 -> 4465 | H14: =H13+1 -> 23 | I14: =Regression!B24 -> 13 | J14: =(LN(I14)-Regression!$B$26)/Regression!$B$27 -> -0.86486743 | K14: 0 | L14: =Regression!F24 -> 385 | M14: =Regression!$I$20+J14*Regression!$I$21+K14*Regression!$I$22 -> 198.97329 | N14: 175 | O14: =MIN(L14,N14) -> 175 | P14: =$B$4*O14-$B$3*N14 -> 12250
A15: =Regression!A19 -> 18 | B15: =P9 -> 73500 | C15: =Q26 -> 80510 | D15: =C15-B15 -> 7010 | P15: =SUM(P2:P14) -> 305505
A16: =Regression!A20 -> 19 | B16: =P10 -> 48800 | C16: =Q27 -> 68250 | D16: =C16-B16 -> 19450
A17: =Regression!A21 -> 20 | B17: =P11 -> 15750 | C17: =Q28 -> 19140 | D17: =C17-B17 -> 3390
A18: =Regression!A22 -> 21 | B18: =P12 -> 7930 | C18: =Q29 -> 9470 | D18: =C18-B18 -> 1540 | H18: LEC ID | I18: Length | J18: Actual demand | K18: Forecast demand | L18: optimal quantity | M18: local capacity | N18: Extra Demand | O18: local quantity | P18: Sales | Q18: profit
A19: =Regression!A23 -> 22 | B19: =P13 -> 15750 | C19: =Q30 -> 15370 | D19: =C19-B19 -> -380 | H19: 11 | I19: =Regression!B12 -> 14 | J19: =Regression!F12 -> 153 | K19: =Regression!$I$20+J2*Regression!$I$21+K2*Regression!$I$22 -> 213.05229 | L19: {=TRANSPOSE('Task 5'!AH7:AT7)} -> 175 | M19: =12 * (I19 - 7) -> 84 | N19: =IF(J19>L19,J19-L19,0) -> 0 | O19: =MIN(M19,N19) -> 0 | P19: =L19+O19 -> 175 | Q19: =$B$4*P19-$B$3*L19-$B$2*O19 -> 12250
A20: =Regression!A24 -> 23 | B20: =P14 -> 12250 | C20: =Q31 -> 15130 | D20: =C20-B20 -> 2880 | H20: =H19+1 -> 12 | I20: =Regression!B13 -> 16 | J20: =Regression!F13 -> 322 | K20: =Regression!$I$20+J3*Regression!$I$21+K3*Regression!$I$22 -> 238.42052 | L20: 225 | M20: =12 * (I20 - 7) -> 108 | N20: =IF(J20>L20,J20-L20,0) -> 97 | O20: =MIN(M20,N20) -> 97 | P20: =L20+O20 -> 322 | Q20: =$B$4*P20-$B$3*L20-$B$2*O20 -> 19630
H21: =H20+1 -> 13 | I21: =Regression!B14 -> 26 | J21: =Regression!F14 -> 298 | K21: =Regression!$I$20+J4*Regression!$I$21+K4*Regression!$I$22 -> 330.65706 | L21: 300 | M21: =12 * (I21 - 7) -> 228 | N21: =IF(J21>L21,J21-L21,0) -> 0 | O21: =MIN(M21,N21) -> 0 | P21: =L21+O21 -> 300 | Q21: =$B$4*P21-$B$3*L21-$B$2*O21 -> 21000
A22: Total | B22: =SUM(B8:B20) -> 305505 | C22: =SUM(C8:C20) -> 372920 | D22: =SUM(D8:D20) -> 67415 | H22: =H21+1 -> 14 | I22: =Regression!B15 -> 16 | J22: =Regression!F15 -> 133 | K22: =Regression!$I$20+J5*Regression!$I$21+K5*Regression!$I$22 -> 238.42052 | L22: 200 | M22: =12 * (I22 - 7) -> 108 | N22: =IF(J22>L22,J22-L22,0) -> 0 | O22: =MIN(M22,N22) -> 0 | P22: =L22+O22 -> 200 | Q22: =$B$4*P22-$B$3*L22-$B$2*O22 -> 14000
H23: =H22+1 -> 15 | I23: =Regression!B16 -> 18 | J23: =Regression!F16 -> 192 | K23: =Regression!$I$20+J6*Regression!$I$21+K6*Regression!$I$22 -> 260.79688 | L23: 225 | M23: =12 * (I23 - 7) -> 132 | N23: =IF(J23>L23,J23-L23,0) -> 0 | O23: =MIN(M23,N23) -> 0 | P23: =L23+O23 -> 225 | Q23: =$B$4*P23-$B$3*L23-$B$2*O23 -> 15750
H24: =H23+1 -> 16 | I24: =Regression!B17 -> 14 | J24: =Regression!F17 -> 198 | K24: =Regression!$I$20+J7*Regression!$I$21+K7*Regression!$I$22 -> 213.05229 | L24: 150 | M24: =12 * (I24 - 7) -> 84 | N24: =IF(J24>L24,J24-L24,0) -> 48 | O24: =MIN(M24,N24) -> 48 | P24: =L24+O24 -> 198 | Q24: =$B$4*P24-$B$3*L24-$B$2*O24 -> 12420
A25: Model | B25: Outsourcing | C25: Near Sourcing | D25: Flexibility | E25: Best Model | H25: =H24+1 -> 17 | I25: =Regression!B18 -> 36 | J25: =Regression!F18 -> 991 | K25: =Regression!$I$20+J8*Regression!$I$21+K8*Regression!$I$22 -> 1047.6988 | L25: 1000 | M25: =12 * (I25 - 7) -> 348 | N25: =IF(J25>L25,J25-L25,0) -> 0 | O25: =MIN(M25,N25) -> 0 | P25: =L25+O25 -> 1000 | Q25: =$B$4*P25-$B$3*L25-$B$2*O25 -> 70000
A26: LEC 11 | B26: =B8 -> 6030 | C26: =C8 -> 12250 | D26: ='Task 9'!P9 -> 6030 | E26: =_xlfn.XLOOKUP(MAX(B26:D26),B26:D26,$B$25:$D$25,0,0,1) -> Near Sourcing | H26: =H25+1 -> 18 | I26: =Regression!B19 -> 35 | J26: =Regression!F19 -> 1244 | K26: =Regression!$I$20+J9*Regression!$I$21+K9*Regression!$I$22 -> 1042.3469 | L26: 1025 | M26: =12 * (I26 - 7) -> 336 | N26: =IF(J26>L26,J26-L26,0) -> 219 | O26: =MIN(M26,N26) -> 219 | P26: =L26+O26 -> 1244 | Q26: =$B$4*P26-$B$3*L26-$B$2*O26 -> 80510
A27: LEC 12 | B27: =B9 -> 15750 | C27: =C9 -> 19630 | D27: ='Task 9'!P10 -> 15960 | E27: =_xlfn.XLOOKUP(MAX(B27:D27),B27:D27,$B$25:$D$25,0,0,1) -> Near Sourcing | H27: =H26+1 -> 19 | I27: =Regression!B20 -> 28 | J27: =Regression!F20 -> 855 | K27: =Regression!$I$20+J10*Regression!$I$21+K10*Regression!$I$22 -> 999.95423 | L27: 975 | M27: =12 * (I27 - 7) -> 252 | N27: =IF(J27>L27,J27-L27,0) -> 0 | O27: =MIN(M27,N27) -> 0 | P27: =L27+O27 -> 975 | Q27: =$B$4*P27-$B$3*L27-$B$2*O27 -> 68250
A28: LEC 13 | B28: =B10 -> 19105 | C28: =C10 -> 21000 | D28: ='Task 9'!P11 -> 18330 | E28: =_xlfn.XLOOKUP(MAX(B28:D28),B28:D28,$B$25:$D$25,0,0,1) -> Near Sourcing | H28: =H27+1 -> 20 | I28: =Regression!B21 -> 17 | J28: =Regression!F21 -> 291 | K28: =Regression!$I$20+J11*Regression!$I$21+K11*Regression!$I$22 -> 249.93796 | L28: 250 | M28: =12 * (I28 - 7) -> 120 | N28: =IF(J28>L28,J28-L28,0) -> 41 | O28: =MIN(M28,N28) -> 41 | P28: =L28+O28 -> 291 | Q28: =$B$4*P28-$B$3*L28-$B$2*O28 -> 19140
A29: LEC 14 | B29: =B11 -> 3330 | C29: =C11 -> 14000 | D29: ='Task 9'!P12 -> 1705 | E29: =_xlfn.XLOOKUP(MAX(B29:D29),B29:D29,$B$25:$D$25,0,0,1) -> Near Sourcing | H29: =H28+1 -> 21 | I29: =Regression!B22 -> 11 | J29: =Regression!F22 -> 143 | K29: =Regression!$I$20+J12*Regression!$I$21+K12*Regression!$I$22 -> 167.23644 | L29: 125 | M29: =12 * (I29 - 7) -> 48 | N29: =IF(J29>L29,J29-L29,0) -> 18 | O29: =MIN(M29,N29) -> 18 | P29: =L29+O29 -> 143 | Q29: =$B$4*P29-$B$3*L29-$B$2*O29 -> 9470
A30: LEC 15 | B30: =B12 -> 8045 | C30: =C12 -> 15750 | D30: ='Task 9'!P13 -> 9800 | E30: =_xlfn.XLOOKUP(MAX(B30:D30),B30:D30,$B$25:$D$25,0,0,1) -> Near Sourcing | H30: =H29+1 -> 22 | I30: =Regression!B23 -> 14 | J30: =Regression!F23 -> 253 | K30: =Regression!$I$20+J13*Regression!$I$21+K13*Regression!$I$22 -> 213.05229 | L30: 175 | M30: =12 * (I30 - 7) -> 84 | N30: =IF(J30>L30,J30-L30,0) -> 78 | O30: =MIN(M30,N30) -> 78 | P30: =L30+O30 -> 253 | Q30: =$B$4*P30-$B$3*L30-$B$2*O30 -> 15370
A31: LEC 16 | B31: =B13 -> 13730 | C31: =C13 -> 12420 | D31: ='Task 9'!P14 -> 13730 | E31: =_xlfn.XLOOKUP(MAX(B31:D31),B31:D31,$B$25:$D$25,0,0,1) -> Outsourcing | H31: =H30+1 -> 23 | I31: =Regression!B24 -> 13 | J31: =Regression!F24 -> 385 | K31: =Regression!$I$20+J14*Regression!$I$21+K14*Regression!$I$22 -> 198.97329 | L31: 175 | M31: =12 * (I31 - 7) -> 72 | N31: =IF(J31>L31,J31-L31,0) -> 210 | O31: =MIN(M31,N31) -> 72 | P31: =L31+O31 -> 247 | Q31: =$B$4*P31-$B$3*L31-$B$2*O31 -> 15130
A32: LEC 17 | B32: =B14 -> 65535 | C32: =C14 -> 70000 | D32: ='Task 9'!P15 -> 69240 | E32: =_xlfn.XLOOKUP(MAX(B32:D32),B32:D32,$B$25:$D$25,0,0,1) -> Near Sourcing | Q32: =SUM(Q19:Q31) -> 372920
A33: LEC 18 | B33: =B15 -> 73500 | C33: =C15 -> 80510 | D33: ='Task 9'!P16 -> 72100 | E33: =_xlfn.XLOOKUP(MAX(B33:D33),B33:D33,$B$25:$D$25,0,0,1) -> Near Sourcing
A34: LEC 19 | B34: =B16 -> 48800 | C34: =C16 -> 68250 | D34: ='Task 9'!P17 -> 47370 | E34: =_xlfn.XLOOKUP(MAX(B34:D34),B34:D34,$B$25:$D$25,0,0,1) -> Near Sourcing
A35: LEC 20 | B35: =B17 -> 15750 | C35: =C17 -> 19140 | D35: ='Task 9'!P18 -> 17190 | E35: =_xlfn.XLOOKUP(MAX(B35:D35),B35:D35,$B$25:$D$25,0,0,1) -> Near Sourcing
A36: LEC 21 | B36: =B18 -> 7930 | C36: =C18 -> 9470 | D36: ='Task 9'!P19 -> 9555 | E36: =_xlfn.XLOOKUP(MAX(B36:D36),B36:D36,$B$25:$D$25,0,0,1) -> Flexibility
A37: LEC 22 | B37: =B19 -> 15750 | C37: =C19 -> 15370 | D37: ='Task 9'!P20 -> 15750 | E37: =_xlfn.XLOOKUP(MAX(B37:D37),B37:D37,$B$25:$D$25,0,0,1) -> Outsourcing
A38: LEC 23 | B38: =B20 -> 12250 | C38: =C20 -> 15130 | D38: ='Task 9'!P21 -> 14000 | E38: =_xlfn.XLOOKUP(MAX(B38:D38),B38:D38,$B$25:$D$25,0,0,1) -> Near Sourcing
A39: Total | B39: =SUM(B26:B38) -> 305505 | C39: =SUM(C26:C38) -> 372920 | D39: =SUM(D26:D38) -> 310760 | E39: =_xlfn.XLOOKUP(MAX(B39:D39),B39:D39,$B$25:$D$25,0,0,1) -> Near Sourcing

Sheet Regression 14d
A1: LEC ID | B1: Length | C1: Remaining Length | D1: Ln(Length) | E1: Total Sold | F1: Normalized Ln(Len) | G1: Contains Holiday | H1: 7 Days Sales | I1: Remaining Sales | J1: Prediction
A2: 1 | B2: 21 | C2: =MAX(0,B2-7) -> 14 | D2: =LN(C2) -> 2.6390573 | E2: 173 | F2: =(D2-$B$26)/$B$27 -> 0.70895317 | G2: 0 | H2: 93 | I2: =E2-H2 -> 80 | J2: =$M$19+F2*$M$20+G2*$M$21+H2*$L$22 -> 152.75739
A3: 2 | B3: 20 | C3: =MAX(0,B3-7) -> 13 | D3: =LN(C3) -> 2.5649494 | E3: 196 | F3: =(D3-$B$26)/$B$27 -> 0.56638515 | G3: 0 | H3: 108 | I3: =E3-H3 -> 88 | J3: =$M$19+F3*$M$20+G3*$M$21+H3*$L$22 -> 146.16754 | L3: SUMMARY OUTPUT
A4: 3 | B4: 13 | C4: =MAX(0,B4-7) -> 6 | D4: =LN(C4) -> 1.7917595 | E4: 195 | F4: =(D4-$B$26)/$B$27 -> -0.92106815 | G4: 0 | H4: 155 | I4: =E4-H4 -> 40 | J4: =$M$19+F4*$M$20+G4*$M$21+H4*$L$22 -> 77.413771
A5: 4 | B5: 15 | C5: =MAX(0,B5-7) -> 8 | D5: =LN(C5) -> 2.0794415 | E5: 210 | F5: =(D5-$B$26)/$B$27 -> -0.36762888 | G5: 0 | H5: 103 | I5: =E5-H5 -> 107 | J5: =$M$19+F5*$M$20+G5*$M$21+H5*$L$22 -> 102.9951 | L5: Regression Statistics
A6: 5 | B6: 13 | C6: =MAX(0,B6-7) -> 6 | D6: =LN(C6) -> 1.7917595 | E6: 291 | F6: =(D6-$B$26)/$B$27 -> -0.92106815 | G6: 0 | H6: 208 | I6: =E6-H6 -> 83 | J6: =$M$19+F6*$M$20+G6*$M$21+H6*$L$22 -> 77.413771 | L6: Multiple R | M6: 0.95273429
A7: 6 | B7: 14 | C7: =MAX(0,B7-7) -> 7 | D7: =LN(C7) -> 1.9459101 | E7: 170 | F7: =(D7-$B$26)/$B$27 -> -0.62451495 | G7: 0 | H7: 103 | I7: =E7-H7 -> 67 | J7: =$M$19+F7*$M$20+G7*$M$21+H7*$L$22 -> 91.121193 | L7: R Square | M7: 0.90770262
A8: 7 | B8: 15 | C8: =MAX(0,B8-7) -> 8 | D8: =LN(C8) -> 2.0794415 | E8: 252 | F8: =(D8-$B$26)/$B$27 -> -0.36762888 | G8: 0 | H8: 163 | I8: =E8-H8 -> 89 | J8: =$M$19+F8*$M$20+G8*$M$21+H8*$L$22 -> 102.9951 | L8: Adjusted R Square | M8: 0.89847289
A9: 8 | B9: 21 | C9: =MAX(0,B9-7) -> 14 | D9: =LN(C9) -> 2.6390573 | E9: 520 | F9: =(D9-$B$26)/$B$27 -> 0.70895317 | G9: 0 | H9: 272 | I9: =E9-H9 -> 248 | J9: =$M$19+F9*$M$20+G9*$M$21+H9*$L$22 -> 152.75739 | L9: Standard Error | M9: 86.3454
A10: 9 | B10: 14 | C10: =MAX(0,B10-7) -> 7 | D10: =LN(C10) -> 1.9459101 | E10: 164 | F10: =(D10-$B$26)/$B$27 -> -0.62451495 | G10: 0 | H10: 83 | I10: =E10-H10 -> 81 | J10: =$M$19+F10*$M$20+G10*$M$21+H10*$L$22 -> 91.121193 | L10: Observations | M10: 23
A11: 10 | B11: 14 | C11: =MAX(0,B11-7) -> 7 | D11: =LN(C11) -> 1.9459101 | E11: 135 | F11: =(D11-$B$26)/$B$27 -> -0.62451495 | G11: 0 | H11: 91 | I11: =E11-H11 -> 44 | J11: =$M$19+F11*$M$20+G11*$M$21+H11*$L$22 -> 91.121193
A12: 11 | B12: 14 | C12: =MAX(0,B12-7) -> 7 | D12: =LN(C12) -> 1.9459101 | E12: 153 | F12: =(D12-$B$26)/$B$27 -> -0.62451495 | G12: 0 | H12: 79 | I12: =E12-H12 -> 74 | J12: =$M$19+F12*$M$20+G12*$M$21+H12*$L$22 -> 91.121193 | L12: ANOVA
A13: 12 | B13: 16 | C13: =MAX(0,B13-7) -> 9 | D13: =LN(C13) -> 2.1972246 | E13: 322 | F13: =(D13-$B$26)/$B$27 -> -0.14103931 | G13: 0 | H13: 116 | I13: =E13-H13 -> 206 | J13: =$M$19+F13*$M$20+G13*$M$21+H13*$L$22 -> 113.46863 | M13: df | N13: SS | O13: MS | P13: F | Q13: Significance F
A14: 13 | B14: 26 | C14: =MAX(0,B14-7) -> 19 | D14: =LN(C14) -> 2.944439 | E14: 298 | F14: =(D14-$B$26)/$B$27 -> 1.2964427 | G14: 0 | H14: 120 | I14: =E14-H14 -> 178 | J14: =$M$19+F14*$M$20+G14*$M$21+H14*$L$22 -> 179.9126 | L14: Regression | M14: 2 | N14: 1466434.4 | O14: 733217.2 | P14: 98.345441 | Q14: 4.4863546e-11
A15: 14 | B15: 16 | C15: =MAX(0,B15-7) -> 9 | D15: =LN(C15) -> 2.1972246 | E15: 133 | F15: =(D15-$B$26)/$B$27 -> -0.14103931 | G15: 0 | H15: 49 | I15: =E15-H15 -> 84 | J15: =$M$19+F15*$M$20+G15*$M$21+H15*$L$22 -> 113.46863 | L15: Residual | M15: 20 | N15: 149110.56 | O15: 7455.5281
A16: 15 | B16: 18 | C16: =MAX(0,B16-7) -> 11 | D16: =LN(C16) -> 2.3978953 | E16: 192 | F16: =(D16-$B$26)/$B$27 -> 0.24500854 | G16: 0 | H16: 114 | I16: =E16-H16 -> 78 | J16: =$M$19+F16*$M$20+G16*$M$21+H16*$L$22 -> 131.31272 | L16: Total | M16: 22 | N16: 1615545
A17: 16 | B17: 14 | C17: =MAX(0,B17-7) -> 7 | D17: =LN(C17) -> 1.9459101 | E17: 198 | F17: =(D17-$B$26)/$B$27 -> -0.62451495 | G17: 0 | H17: 80 | I17: =E17-H17 -> 118 | J17: =$M$19+F17*$M$20+G17*$M$21+H17*$L$22 -> 91.121193
A18: 17 | B18: 36 | C18: =MAX(0,B18-7) -> 29 | D18: =LN(C18) -> 3.3672958 | E18: 991 | F18: =(D18-$B$26)/$B$27 -> 2.1099295 | G18: 1 | H18: 136 | I18: =E18-H18 -> 855 | J18: =$M$19+F18*$M$20+G18*$M$21+H18*$L$22 -> 861.94071 | M18: Coefficients | N18: Standard Error | O18: t Stat | P18: P-value | Q18: Lower 95% | R18: Upper 95% | S18: Lower 95,0% | T18: Upper 95,0%
A19: 18 | B19: 35 | C19: =MAX(0,B19-7) -> 28 | D19: =LN(C19) -> 3.3322045 | E19: 1244 | F19: =(D19-$B$26)/$B$27 -> 2.0424213 | G19: 1 | H19: 168 | I19: =E19-H19 -> 1076 | J19: =$M$19+F19*$M$20+G19*$M$21+H19*$L$22 -> 858.82031 | L19: Intercept | M19: 119.98782 | N19: 20.815881 | O19: 5.7642441 | P19: 1.2193206e-05 | Q19: 76.566651 | R19: 163.40898 | S19: 76.566651 | T19: 163.40898
A20: 19 | B20: 28 | C20: =MAX(0,B20-7) -> 21 | D20: =LN(C20) -> 3.0445224 | E20: 855 | F20: =(D20-$B$26)/$B$27 -> 1.488982 | G20: 1 | H20: 232 | I20: =E20-H20 -> 623 | J20: =$M$19+F20*$M$20+G20*$M$21+H20*$L$22 -> 833.23898 | L20: X Variable 1 | M20: 46.222472 | N20: 27.581244 | O20: 1.6758661 | P20: 0.10932843 | Q20: -11.310994 | R20: 103.75594 | S20: -11.310994 | T20: 103.75594
A21: 20 | B21: 17 | C21: =MAX(0,B21-7) -> 10 | D21: =LN(C21) -> 2.3025851 | E21: 291 | F21: =(D21-$B$26)/$B$27 -> 0.061651971 | G21: 0 | H21: 206 | I21: =E21-H21 -> 85 | J21: =$M$19+F21*$M$20+G21*$M$21+H21*$L$22 -> 122.83752 | L21: X Variable 2 | M21: 644.42673 | N21: 80.096489 | O21: 8.0456303 | P21: 1.0674876e-07 | Q21: 477.34839 | R21: 811.50508 | S21: 477.34839 | T21: 811.50508
A22: 21 | B22: 11 | C22: =MAX(0,B22-7) -> 4 | D22: =LN(C22) -> 1.3862944 | E22: 143 | F22: =(D22-$B$26)/$B$27 -> -1.701097 | G22: 0 | H22: 104 | I22: =E22-H22 -> 39 | J22: =$M$19+F22*$M$20+G22*$M$21+H22*$L$22 -> 41.358909
A23: 22 | B23: 14 | C23: =MAX(0,B23-7) -> 7 | D23: =LN(C23) -> 1.9459101 | E23: 253 | F23: =(D23-$B$26)/$B$27 -> -0.62451495 | G23: 0 | H23: 117 | I23: =E23-H23 -> 136 | J23: =$M$19+F23*$M$20+G23*$M$21+H23*$L$22 -> 91.121193
A24: 23 | B24: 13 | C24: =MAX(0,B24-7) -> 6 | D24: =LN(C24) -> 1.7917595 | E24: 385 | F24: =(D24-$B$26)/$B$27 -> -0.92106815 | G24: 0 | H24: 171 | I24: =E24-H24 -> 214 | J24: =$M$19+F24*$M$20+G24*$M$21+H24*$L$22 -> 77.413771
A26: Mean Ln(Len) | B26: =AVERAGE(D2:D24) -> 2.2705379
A27: Std.Dev. Ln(Len) | B27: =_xlfn.STDEV.S(D2:D24) -> 0.51980784

Sheet Task 8
A1: Cost Ukraine | B1: 65
A2: Price | B2: 135
A3: Std. Dev. LEC 24 | B3: ='Regression 14d'!M9 -> 86.3454
A4: Initial Order Size | B4: =_xlfn.XLOOKUP(D8,'Task 9'!A9:A21,'Task 9'!J9:J21,1,0,1) -> 420 | P4: Max Profit | Q4: =MAX(Q8:Q68) -> 6523.8428 | R4: =MAX(R8:R68) -> 12693.09 | S4: =MAX(S8:S68) -> 16657.264 | T4: =MAX(T8:T68) -> 5501.7057 | U4: =MAX(U8:U68) -> 13754.823 | V4: =MAX(V8:V68) -> 7285.6555 | W4: =MAX(W8:W68) -> 66201.913 | X4: =MAX(X8:X68) -> 68138.856 | ... AC4: =MAX(AC8:AC68) -> 12375.923
A5: 7d Demand | B5: =_xlfn.XLOOKUP(D8,'Task 9'!A9:A21,'Task 9'!E9:E21,0,1,1) -> 168 | P5: Best Order Size | Q5: =_xlfn.XLOOKUP(Q4,Q8:Q68,$P$8:$P$68,0,0,1) -> 10 | R5: =_xlfn.XLOOKUP(R4,R8:R68,$P$8:$P$68,0,0,1) -> 10 | S5: =_xlfn.XLOOKUP(S4,S8:S68,$P$8:$P$68,0,0,1) -> 110 | T5: =_xlfn.XLOOKUP(T4,T8:T68,$P$8:$P$68,0,0,1) -> 10 | U5: =_xlfn.XLOOKUP(U4,U8:U68,$P$8:$P$68,0,0,1) -> 35 | V5: =_xlfn.XLOOKUP(V4,V8:V68,$P$8:$P$68,0,0,1) -> 10 | W5: =_xlfn.XLOOKUP(W4,W8:W68,$P$8:$P$68,0,0,1) -> 585 | X5: =_xlfn.XLOOKUP(X4,X8:X68,$P$8:$P$68,0,0,1) -> 610 | ... AC5: =_xlfn.XLOOKUP(AC4,AC8:AC68,$P$8:$P$68,0,0,1) -> 10
A6: Remaining Expected | B6: =_xlfn.XLOOKUP(D8,'Task 9'!A9:A21,'Task 9'!I9:I21,0,0,1) -> 858.82031
A7: Length | B7: =_xlfn.XLOOKUP(D8,'Task 9'!A9:A21,'Task 9'!B9:B21,0,0,1) -> 35 | D7: LEC | E7: Flexibility Order | F7: Avg. Profit (Near-sourcing) | P7: =F8 -> 64849.07 | Q7: {=TRANSPOSE('Task 9'!A9:A21)} -> 11 | R7: 12 | S7: 13 | T7: 14 | U7: 15 | V7: 16 | W7: 17 | X7: 18 | Y7: 19 | Z7: 20 | AA7: 21 | AB7: 22 | AC7: 23
A8: 2nd week part | B8: =MIN(1,7/(B7-7)) -> 0.25 | D8: 18 | E8: 700 | F8: =AVERAGE(L12:L1515) -> 64849.07 | P8: 10 | Q8: 6523.8428 | R8: 12693.09 | S8: 12859.067 | T8: 5501.7057 | U8: 13710.247 | V8: 7285.6555 | W8: 29260 | X8: 30100 | Y8: 34790 | Z8: 16288.739 | AA8: 7162.6421 | AB8: 10005.217 | AC8: 12375.923
P9: 35 | Q9: 5257.6087 | R9: 11719.883 | S9: 14322.813 | T9: 4312.0468 | U9: 13754.823 | V9: 5844.3278 | W9: 31010 | X9: 31850 | Y9: 36540 | Z9: 16891.375 | AA9: 5502.2441 | AB9: 8340.9365 | AC9: 10845.378
P10: 60 | Q10: 3403.8763 | R10: 10364.341 | S10: 15546.629 | T10: 2500.9365 | U10: 13034.007 | V10: 4047.0334 | W10: 32760 | X10: 33600 | Y10: 38290 | Z10: 16469.635 | AA10: 3871.7358 | AB10: 6902.3177 | AC10: 9190.5786
C11: Initial Order | D11: Demand 1 week | E11: Remaining after 1 week | F11: Flexibility Order | G11: Demand 2 week | H11: Demand Remaining | I11: Sales first 14d | J11: Sales Remaining | K11: Total sales | L11: Profit | P11: 85 | Q11: 1713.9498 | R11: 9030.2007 | S11: 16366.167 | T11: 925.3311 | U11: 11844.167 | V11: 2627.2876 | W11: 34510 | X11: 35350 | Y11: 40040 | Z11: 14923.197 | AA11: 2418.3077 | AB11: 5408.6154 | AC11: 7506.4314
C12: =$B$4 -> 420 | D12: =$B$5 -> 168 | E12: =MAX(0,C12-D12) -> 252 | F12: =$E$8 -> 700 | G12: =_xlfn.FLOOR.MATH(MAX(0,_xlfn.NORM.INV(RAND(),$B$6*$B$8,$B$3*($B$8+0.0001)))) -> 183 | H12: =_xlfn.FLOOR.MATH(MAX(0,_xlfn.NORM.INV(RAND(),$B$6*(1-$B$8),$B$3*(1.00001-$B$8)))) -> 627 | I12: =MIN(C12,D12+G12) -> 351 | J12: =MIN(C12-I12+F12,H12) -> 627 | K12: =I12+J12 -> 978 | L12: =K12*$B$2-(F12+C12)*$B$1 -> 59230 | P12: 110 | Q12: 437.51171 | R12: 7620.2074 | S12: 16657.264 | T12: -610.3612 | U12: 10035.585 | V12: 937.81271 | W12: 36260 | X12: 37100 | Y12: 41790 | Z12: 13357.977 | AA12: 718.08696 | AB12: 3704.2408 | AC12: 5921.1639
C13: =$B$4 -> 420 | D13: =$B$5 -> 168 | E13: =MAX(0,C13-D13) -> 252 | F13: =$E$8 -> 700 | G13: =_xlfn.FLOOR.MATH(MAX(0,_xlfn.NORM.INV(RAND(),$B$6*$B$8,$B$3*($B$8+0.0001)))) -> 252 | H13: =_xlfn.FLOOR.MATH(MAX(0,_xlfn.NORM.INV(RAND(),$B$6*(1-$B$8),$B$3*(1.00001-$B$8)))) -> 642 | I13: =MIN(C13,D13+G13) -> 420 | J13: =MIN(C13-I13+F13,H13) -> 642 | K13: =I13+J13 -> 1062 | L13: =K13*$B$2-(F13+C13)*$B$1 -> 70570 | P13: 135 | Q13: -1302.6221 | R13: 5664.2542 | S13: 16375.853 | T13: -2243.5786 | U13: 8619.0903 | V13: -698.83612 | W13: 38010 | X13: 38850 | Y13: 43540 | Z13: 11709.679 | AA13: -868.08361 | AB13: 2104.0736 | AC13: 4334.9933
C14: =$B$4 -> 420 | D14: =$B$5 -> 168 | E14: =MAX(0,C14-D14) -> 252 | F14: =$E$8 -> 700 | G14: =_xlfn.FLOOR.MATH(MAX(0,_xlfn.NORM.INV(RAND(),$B$6*$B$8,$B$3*($B$8+0.0001)))) -> 238 | H14: =_xlfn.FLOOR.MATH(MAX(0,_xlfn.NORM.INV(RAND(),$B$6*(1-$B$8),$B$3*(1.00001-$B$8)))) -> 575 | I14: =MIN(C14,D14+G14) -> 406 | J14: =MIN(C14-I14+F14,H14) -> 575 | K14: =I14+J14 -> 981 | L14: =K14*$B$2-(F14+C14)*$B$1 -> 59635 | P14: 160 | Q14: -3341.5619 | R14: 3983.99 | S14: 15472.448 | T14: -4085.3913 | U14: 7138.2107 | V14: -2362.6656 | W14: 39760 | X14: 40600 | Y14: 45290 | Z14: 10076.552 | AA14: -2545.4582 | AB14: 299.73579 | AC14: 2645.9699
C15: =$B$4 -> 420 | D15: =$B$5 -> 168 | E15: =MAX(0,C15-D15) -> 252 | F15: =$E$8 -> 700 | G15: =_xlfn.FLOOR.MATH(MAX(0,_xlfn.NORM.INV(RAND(),$B$6*$B$8,$B$3*($B$8+0.0001)))) -> 184 | H15: =_xlfn.FLOOR.MATH(MAX(0,_xlfn.NORM.INV(RAND(),$B$6*(1-$B$8),$B$3*(1.00001-$B$8)))) -> 620 | I15: =MIN(C15,D15+G15) -> 352 | J15: =MIN(C15-I15+F15,H15) -> 620 | K15: =I15+J15 -> 972 | L15: =K15*$B$2-(F15+C15)*$B$1 -> 58420 | P15: 185 | Q15: -4802.7559 | R15: 2535.9799 | S15: 14270.147 | T15: -5441.7458 | U15: 5472.9365 | V15: -3781.689 | W15: 41510 | X15: 42350 | Y15: 47040 | Z15: 8337.1405 | AA15: -3992.204 | AB15: -1198.5719 | AC15: 1030.7224
C16: =$B$4 -> 420 | D16: =$B$5 -> 168 | E16: =MAX(0,C16-D16) -> 252 | F16: =$E$8 -> 700 | G16: =_xlfn.FLOOR.MATH(MAX(0,_xlfn.NORM.INV(RAND(),$B$6*$B$8,$B$3*($B$8+0.0001)))) -> 206 | H16: =_xlfn.FLOOR.MATH(MAX(0,_xlfn.NORM.INV(RAND(),$B$6*(1-$B$8),$B$3*(1.00001-$B$8)))) -> 673 | I16: =MIN(C16,D16+G16) -> 374 | J16: =MIN(C16-I16+F16,H16) -> 673 | K16: =I16+J16 -> 1047 | L16: =K16*$B$2-(F16+C16)*$B$1 -> 68545 | P16: 210 | Q16: -6011.1973 | R16: 696.60535 | S16: 12896.816 | T16: -7422.0803 | U16: 3763.4147 | V16: -6049.1806 | W16: 43260 | X16: 44100 | Y16: 48790 | Z16: 6986.5652 | AA16: -5745.3411 | AB16: -2830.5251 | AC16: -587.23411
C17: =$B$4 -> 420 | D17: =$B$5 -> 168 | E17: =MAX(0,C17-D17) -> 252 | F17: =$E$8 -> 700 | G17: =_xlfn.FLOOR.MATH(MAX(0,_xlfn.NORM.INV(RAND(),$B$6*$B$8,$B$3*($B$8+0.0001)))) -> 239 | H17: =_xlfn.FLOOR.MATH(MAX(0,_xlfn.NORM.INV(RAND(),$B$6*(1-$B$8),$B$3*(1.00001-$B$8)))) -> 653 | I17: =MIN(C17,D17+G17) -> 407 | J17: =MIN(C17-I17+F17,H17) -> 653 | K17: =I17+J17 -> 1060 | L17: =K17*$B$2-(F17+C17)*$B$1 -> 70300 | P17: 235 | Q17: -8186.5819 | R17: -829.60535 | S17: 11320.849 | T17: -8413.1672 | U17: 1934.6957 | V17: -7183.6656 | W17: 45010 | X17: 45850 | Y17: 50540 | Z17: 5163.0836 | AA17: -7423.0769 | AB17: -4481.7124 | AC17: -2213.9498
C18: =$B$4 -> 420 | D18: =$B$5 -> 168 | E18: =MAX(0,C18-D18) -> 252 | F18: =$E$8 -> 700 | G18: =_xlfn.FLOOR.MATH(MAX(0,_xlfn.NORM.INV(RAND(),$B$6*$B$8,$B$3*($B$8+0.0001)))) -> 207 | H18: =_xlfn.FLOOR.MATH(MAX(0,_xlfn.NORM.INV(RAND(),$B$6*(1-$B$8),$B$3*(1.00001-$B$8)))) -> 683 | I18: =MIN(C18,D18+G18) -> 375 | J18: =MIN(C18-I18+F18,H18) -> 683 | K18: =I18+J18 -> 1058 | L18: =K18*$B$2-(F18+C18)*$B$1 -> 70030 | P18: 260 | Q18: -9691.5719 | R18: -2431.9398 | S18: 9671.3779 | T18: -10231.773 | U18: 794.70234 | V18: -8876.2107 | W18: 46760 | X18: 47600 | Y18: 52290 | Z18: 3810.7023 | AA18: -9079.8629 | AB18: -6254.8963 | AC18: -3765.4448
C19: =$B$4 -> 420 | D19: =$B$5 -> 168 | E19: =MAX(0,C19-D19) -> 252 | F19: =$E$8 -> 700 | G19: =_xlfn.FLOOR.MATH(MAX(0,_xlfn.NORM.INV(RAND(),$B$6*$B$8,$B$3*($B$8+0.0001)))) -> 203 | H19: =_xlfn.FLOOR.MATH(MAX(0,_xlfn.NORM.INV(RAND(),$B$6*(1-$B$8),$B$3*(1.00001-$B$8)))) -> 648 | I19: =MIN(C19,D19+G19) -> 371 | J19: =MIN(C19-I19+F19,H19) -> 648 | K19: =I19+J19 -> 1019 | L19: =K19*$B$2-(F19+C19)*$B$1 -> 64765 | P19: 285 | Q19: -11213.9 | R19: -4194.9197 | S19: 7997.7057 | T19: -11871.672 | U19: -1068.602 | V19: -10740.508 | W19: 48510 | X19: 49350 | Y19: 54040 | Z19: 2167.1906 | AA19: -10562.187 | AB19: -7970.7391 | AC19: -5434.7826
C20: =$B$4 -> 420 | D20: =$B$5 -> 168 | E20: =MAX(0,C20-D20) -> 252 | F20: =$E$8 -> 700 | G20: =_xlfn.FLOOR.MATH(MAX(0,_xlfn.NORM.INV(RAND(),$B$6*$B$8,$B$3*($B$8+0.0001)))) -> 201 | H20: =_xlfn.FLOOR.MATH(MAX(0,_xlfn.NORM.INV(RAND(),$B$6*(1-$B$8),$B$3*(1.00001-$B$8)))) -> 775 | I20: =MIN(C20,D20+G20) -> 369 | J20: =MIN(C20-I20+F20,H20) -> 751 | K20: =I20+J20 -> 1120 | L20: =K20*$B$2-(F20+C20)*$B$1 -> 78400 | P20: 310 | Q20: -12895.789 | R20: -5729.4381 | S20: 6060.9866 | T20: -13876.839 | U20: -2614.1371 | V20: -12216.421 | W20: 50260 | X20: 51100 | Y20: 55790 | Z20: 457.5786 | AA20: -12325.528 | AB20: -9534.3344 | AC20: -7034.7692
